<?xml version="1.0"?>
<robot xmlns:xacro="http://www.ros.org/wiki/xacro"  name="robot">

    <xacro:include filename='inertial_macros.xacro'/>

    <xacro:property name="chassis_length" value="0.300"/>
    <xacro:property name="chassis_width" value="0.300"/>
    <xacro:property name="chassis_height" value="0.150"/>
    <xacro:property name="chassis_mass" value="0.5"/>
    <xacro:property name="wheel_radius" value="0.05"/>
    <xacro:property name="wheel_thickness" value="0.04"/>
    <xacro:property name="wheel_mass" value="0.1"/>
    <xacro:property name="wheel_offset_x" value="0.2"/>

    <material name="white">
        <color rgba="1 1 1 1 "/>
    </material>

    <material name="orange">
        <color rgba="1 0.3 0.1 1 "/>
    </material>

    <material name="blue">
        <color rgba="0.2 0.2 1 1 "/>
    </material>

    <material name="black">
        <color rgba="0 0 0 1 "/>
    </material>

    <material name="red">
        <color rgba="1 0 0 1 "/>
    </material>

    <!-- BASE LINK -->
    
    <link name="base_link">
    
    </link>

    <!-- CHASSIS LINK -->

    <joint name="chassis_joint" type="fixed">
        <parent link="base_link"/>
        <child link="chassis"/>
        <origin xyz="-0.15 0 0"/>
    </joint>

    <link name="chassis">
        <visual>
            <origin xyz="0.15 0 0.075"/>
            <geometry>
                <box size="0.3 0.3 0.15"/>
            </geometry>
            <material name="white"/>
        </visual>
        <collision>
            <origin xyz="0.15 0 0.075"/>
            <geometry>
                <box size="0.3 0.3 0.15"/>
            </geometry>
        </collision>
        <xacro:inertial_box mass="0.5" x="0.3" y="0.3" z="0.15">
            <origin xyz="0.16 0 0.075" rpy="0 0 0"/>
        </xacro:inertial_box>
    </link>

    <gazebo reference='chassis'>
        <material>Gazebo/White</material>
    </gazebo>

    <!-- FRONT LEFT WHEEL LINK -->
    <joint name="fl_wheel_joint" type="continuous">
        <parent link="base_link"/>
        <child link="fl_wheel"/>
        <origin xyz="0.1 0.175 0" rpy="-${pi/2} 0 0"/>
        <axis xyz="0 0 1"/>
    </joint>

    <link name="fl_wheel">
        <visual>
            <geometry>
                <cylinder radius="0.05" length="0.04"/>
            </geometry>
            <material name="blue"/>
        </visual>
        <collision>
            <geometry>
                <cylinder radius="0.05" length="0.04"/>
            </geometry>
        </collision>
        <xacro:inertial_cylinder mass="0.1" length="0.04" radius="0.05">
            <origin xyz="0 0 0" rpy="0 0 0"/>
        </xacro:inertial_cylinder>
    </link>

    <gazebo reference='fl_wheel'>
        <material>Gazebo/Blue</material>
    </gazebo>

    <!-- FRONT RIGHT WHEEL LINK -->
    <joint name="fr_wheel_joint" type="continuous">
        <parent link="base_link"/>
        <child link="fr_wheel"/>
        <origin xyz="0.1 -0.175 0" rpy="${pi/2} 0 0"/>
        <axis xyz="0 0 -1"/>
    </joint>

    <link name="fr_wheel">
        <visual>
            <geometry>
                <cylinder radius="0.05" length="0.04"/>
            </geometry>
            <material name="blue"/>
        </visual>
        <collision>
            <geometry>
                <cylinder radius="0.05" length="0.04"/>
            </geometry>
        </collision>
        <xacro:inertial_cylinder mass="0.1" length="0.04" radius="0.05">
            <origin xyz="0 0 0" rpy="0 0 0"/>
        </xacro:inertial_cylinder>
    </link>

    <gazebo reference='fr_wheel'>
        <material>Gazebo/Blue</material>
    </gazebo>

    <!-- REAR LEFT WHEEL LINK -->
    <joint name="rl_wheel_joint" type="continuous">
        <parent link="base_link"/>
        <child link="rl_wheel"/>
        <origin xyz="-0.1 0.175 0" rpy="-${pi/2} 0 0"/>
        <axis xyz="0 0 1"/>
    </joint>

    <link name="rl_wheel">
        <visual>
            <geometry>
                <cylinder radius="0.05" length="0.04"/>
            </geometry>
            <material name="blue"/>
        </visual>
        <collision>
            <geometry>
                <cylinder radius="0.05" length="0.04"/>
            </geometry>
        </collision>
        <xacro:inertial_cylinder mass="0.1" length="0.04" radius="0.05">
            <origin xyz="0 0 0" rpy="0 0 0"/>
        </xacro:inertial_cylinder>
    </link>

    <gazebo reference='rl_wheel'>
        <material>Gazebo/Blue</material>
    </gazebo>

    <!-- REAR RIGHT WHEEL LINK -->
    <joint name="rr_wheel_joint" type="continuous">
        <parent link="base_link"/>
        <child link="rr_wheel"/>
        <origin xyz="-0.1 -0.175 0" rpy="${pi/2} 0 0"/>
        <axis xyz="0 0 -1"/>
    </joint>

    <link name="rr_wheel">
        <visual>
            <geometry>
                <cylinder radius="0.05" length="0.04"/>
            </geometry>
            <material name="blue"/>
        </visual>
        <collision>
            <geometry>
                <cylinder radius="0.05" length="0.04"/>
            </geometry>
        </collision>
        <xacro:inertial_cylinder mass="0.1" length="0.04" radius="0.05">
            <origin xyz="0 0 0" rpy="0 0 0"/>
        </xacro:inertial_cylinder>
    </link>

    <gazebo reference='rr_wheel'>
        <material>Gazebo/Blue</material>
    </gazebo>


</robot>